<?xml version="1.0" encoding="utf-8" standalone="yes"?><rss version="2.0" xmlns:atom="http://www.w3.org/2005/Atom"><channel><title>tornado on Blog</title><link>https://imomaliev.github.io/blog/tags/tornado/</link><description>Recent content in tornado on Blog</description><generator>Hugo -- gohugo.io</generator><language>en-us</language><lastBuildDate>Thu, 30 Sep 2021 22:12:13 +0700</lastBuildDate><atom:link href="https://imomaliev.github.io/blog/tags/tornado/index.xml" rel="self" type="application/rss+xml"/><item><title>Tornado | Fix "tornado.util.TimeoutError: Operation timed out after 5 seconds"</title><link>https://imomaliev.github.io/blog/tils/tornado-fix-timeouterror-on-debug/</link><pubDate>Thu, 30 Sep 2021 22:12:13 +0700</pubDate><guid>https://imomaliev.github.io/blog/tils/tornado-fix-timeouterror-on-debug/</guid><description>Tornado | Fix tornado.util.TimeoutError: Operation timed out after 5 seconds Story Whenever I debug my test for tornado code in the end I get this error
... &amp;gt; raise TimeoutError(&amp;#39;Operation timed out after %sseconds&amp;#39; % timeout) E tornado.util.TimeoutError: Operation timed out after 5 seconds .venv/lib/python3.7/site-packages/tornado/ioloop.py:575: TimeoutError Question How to fix tornado.util.TimeoutError: Operation timed out after 5 seconds on tornado test debug?
Answer This is due ASYNC_TEST_TIMEOUT environment variable From docs</description></item></channel></rss>